# 前言

实验环境

```
OS: Fedora Silverblue
Editor: PyCharm-Community(flatpak)
Pytorch: cuda=12.1, python=3.12
```

包依赖

* matplotlib==3.8.4
* numpy==1.26.4
* Pillow==10.4.0
* tqdm==4.66.4
* wandb==0.17.5

# 初次运行

默认数据集[Carvana Image Masking Challenge](https://www.kaggle.com/c/carvana-image-masking-challenge/data)

wandb记录了[本次运行情况](https://wandb.ai/anony-mouse-721423276759826725/U-Net/runs/e4bc00ym/overview)

    INFO: Starting training:
    Epochs:          3
    Batch size:      2
    Learning rate:   1e-05
    Training size:   4580
    Validation size: 508
    Checkpoints:     True
    Device:          cuda
    Images scaling:  0.5
    Mixed Precision: False

运行正常，一段时间后手动终止。

# Cellpose数据集

显然会报错，疑似文件命名问题。

Function Call Chain:

1. `train.py` calls `train_model`, which creates a `CarvanaDataset` or `BasicDataset` instance.
2. The `CarvanaDataset` or `BasicDataset` initializer calls the parent class (`BasicDataset`) initializer.
3. The parent class initializer calls `unique_mask_values`.
4. The error occurs in `unique_mask_values`:
   ```python
   mask_file = list(mask_dir.glob(idx + mask_suffix + '.*'))[0]
   ```

debug发现 **mask_suffix = '_mask'** ，而cellpose数据集的命名是 **'_masks'**。

找到相关函数

```python
class CarvanaDataset(BasicDataset):
    def __init__(self, images_dir, mask_dir, scale=1):
        super().__init__(images_dir, mask_dir, scale, mask_suffix='_mask')
```

更改后依然报错，排查后发现原图命名错误导致无法正常匹配。去掉原图的命名后缀"_img"。

数据集能够正常加载，出现新的报错如下：

```text
RuntimeError: stack expects each tensor to be equal size, but got [3, 102, 110] at entry 0 and [3, 256, 256] at entry 1
```

第二天重新运行准备看看Traceback，出现新的报错：

```text
RuntimeError: CUDA error: device-side assert triggered
CUDA kernel errors might be asynchronously reported at some other API call, so the stacktrace below might be incorrect.
For debugging consider passing CUDA_LAUNCH_BLOCKING=1.
Compile with `TORCH_USE_CUDA_DSA` to enable device-side assertions.
```

添加环境变量`CUDA_LAUNCH_BLOCKING=1`后，
检查报错内容发现是`torch.nn.CrossEntropyLoss`函数出错

指定超参数`classes=1`，跳过这部分报错代码。

出现新的报错：

```text
Traceback (most recent call last):
  File "/var/home/chumi/Documents/Pytorch-UNet/train.py", line 213, in <module>
    train_model(
  File "/var/home/chumi/Documents/Pytorch-UNet/train.py", line 123, in train_model
    experiment.log({
    ^^^^^^^^^^
NameError: name 'experiment' is not defined
```
`expertiment`继承`wandb.init`，考虑到后续有多处使用该对象，取消前文wandb的注释。

出现新的报错：

```text
Traceback (most recent call last):
  File "/var/home/chumi/Documents/Pytorch-UNet/train.py", line 213, in <module>
    train_model(
  File "/var/home/chumi/Documents/Pytorch-UNet/train.py", line 142, in train_model
    val_score = evaluate(model, val_loader, device, amp)
                ^^^^^^^^^^^^^^^^^^^^^^^^^^^^^^^^^^^^^^^^
  File "/var/home/chumi/anaconda3/envs/unet/lib/python3.12/site-packages/torch/utils/_contextlib.py", line 115, in decorate_context
    return func(*args, **kwargs)
           ^^^^^^^^^^^^^^^^^^^^^
  File "/var/home/chumi/Documents/Pytorch-UNet/evaluate.py", line 27, in evaluate
    assert mask_true.min() >= 0 and mask_true.max() <= 1, 'True mask indices should be in [0, 1]'
           ^^^^^^^^^^^^^^^^^^^^^^^^^^^^^^^^^^^^^^^^^^^^^
AssertionError: True mask indices should be in [0, 1]
```

调试发现，`mask_true`范围是[0, 75]超出要求的[0, 1]

```python
# Let the range of mask_true be [0, 1]
max_value = mask_true.max().item()
mask_true = mask_true / max_value
```

报错如下：

```text
Traceback (most recent call last):
  File "/var/home/chumi/Documents/Pytorch-UNet/train.py", line 213, in <module>
    train_model(
  File "/var/home/chumi/Documents/Pytorch-UNet/train.py", line 142, in train_model
    val_score = evaluate(model, val_loader, device, amp)
                ^^^^^^^^^^^^^^^^^^^^^^^^^^^^^^^^^^^^^^^^
  File "/var/home/chumi/anaconda3/envs/unet/lib/python3.12/site-packages/torch/utils/_contextlib.py", line 115, in decorate_context
    return func(*args, **kwargs)
           ^^^^^^^^^^^^^^^^^^^^^
  File "/var/home/chumi/Documents/Pytorch-UNet/evaluate.py", line 34, in evaluate
    dice_score += dice_coeff(mask_pred, mask_true, reduce_batch_first=False)
                  ^^^^^^^^^^^^^^^^^^^^^^^^^^^^^^^^^^^^^^^^^^^^^^^^^^^^^^^^^^
  File "/var/home/chumi/Documents/Pytorch-UNet/utils/dice_score.py", line 7, in dice_coeff
    assert input.size() == target.size()
           ^^^^^^^^^^^^^^^^^^^^^^^^^^^^^
AssertionError
```

然而实际检查发现`input.size()`和`target.size()`为相同值，
可能并不是每次调用该函数都是相同值。

在报错代码前添加`print(input.size(), target.size())`用于调试。

在报错时`input.size()`多了一个维度且数值为1。

# 部分除错记录

1. 环境指定包版本与Pytorch冲突，取消对应包的版本限制。
2. Kaggle下载数据，出现403 Forbidden。去对应网站同意规则。
3. 实验最初使用VSCode，调试不太方便遂改用PyCharm。
4. 调试阶段关闭wandb功能。
